<?xml version="1.0" encoding="utf-8"?>
<!-- This URDF was automatically created by SolidWorks to URDF Exporter! Originally created by Stephen Brawner (brawner@gmail.com) 
     Commit Version: 1.5.1-0-g916b5db  Build Version: 1.5.7152.31018
     For more information, please see http://wiki.ros.org/sw_urdf_exporter -->
<robot
  name="CK_9_urdf">
  <link
    name="base_link">
    <inertial>
      <origin
        xyz="0.00047536 0.0058752 0.017326"
        rpy="0 0 0" />
      <mass
        value="1.31" />
      <inertia
        ixx="0.0026283"
        ixy="-4.0492E-07"
        ixz="4.9594E-06"
        iyy="0.0049179"
        iyz="-2.0793E-05"
        izz="0.0024465" />
    </inertial>
    <visual>
      <origin
        xyz="0 0 0"
        rpy="0 0 0" />
      <geometry>
        <mesh
          filename="package://CK_9_urdf/meshes/base_link.STL" />
      </geometry>
      <material
        name="">
        <color
          rgba="0.79216 0.81961 0.93333 1" />
      </material>
    </visual>
    <collision>
      <origin
        xyz="0 0 0"
        rpy="0 0 0" />
      <geometry>
        <mesh
          filename="package://CK_9_urdf/meshes/base_link.STL" />
      </geometry>
    </collision>
  </link>
  <link
    name="link_1">
    <inertial>
      <origin
        xyz="-4.78557275201247E-06 2.05292165211812E-10 -0.00886551202445374"
        rpy="0 0 0" />
      <mass
        value="0.0295397059682993" />
      <inertia
        ixx="1.22635694817841E-05"
        ixy="-3.42533984537833E-14"
        ixz="4.29598342141542E-10"
        iyy="1.22628392612287E-05"
        iyz="-1.30969227999568E-14"
        izz="2.32051343349445E-05" />
    </inertial>
    <visual>
      <origin
        xyz="0 0 0"
        rpy="0 0 0" />
      <geometry>
        <mesh
          filename="package://CK_9_urdf/meshes/link_1.STL" />
      </geometry>
      <material
        name="">
        <color
          rgba="0.792156862745098 0.819607843137255 0.933333333333333 1" />
      </material>
    </visual>
    <collision>
      <origin
        xyz="0 0 0"
        rpy="0 0 0" />
      <geometry>
        <mesh
          filename="package://CK_9_urdf/meshes/link_1.STL" />
      </geometry>
    </collision>
  </link>
  <joint
    name="joint_1"
    type="continuous">
    <origin
      xyz="-0.15578 0.00055476 0.042685"
      rpy="-1.5708 0 -1.5708" />
    <parent
      link="base_link" />
    <child
      link="link_1" />
    <axis
      xyz="0 0 0" />
  </joint>
  <link
    name="link_2">
    <inertial>
      <origin
        xyz="-4.7858E-06 3.0225E-10 0.0088655"
        rpy="0 0 0" />
      <mass
        value="0.01" />
      <inertia
        ixx="1.2264E-05"
        ixy="-5.0951E-14"
        ixz="-4.2958E-10"
        iyy="1.2263E-05"
        iyz="1.1126E-14"
        izz="2.3205E-05" />
    </inertial>
    <visual>
      <origin
        xyz="0 0 0"
        rpy="0 0 0" />
      <geometry>
        <mesh
          filename="package://CK_9_urdf/meshes/link_2.STL" />
      </geometry>
      <material
        name="">
        <color
          rgba="0.79216 0.81961 0.93333 1" />
      </material>
    </visual>
    <collision>
      <origin
        xyz="0 0 0"
        rpy="0 0 0" />
      <geometry>
        <mesh
          filename="package://CK_9_urdf/meshes/link_2.STL" />
      </geometry>
    </collision>
  </link>
  <joint
    name="joint_2"
    type="continuous">
    <origin
      xyz="0 0 0.31156"
      rpy="0 0 0" />
    <parent
      link="link_1" />
    <child
      link="link_2" />
    <axis
      xyz="0 0 0" />
  </joint>
  <link
    name="link_3">
    <inertial>
      <origin
        xyz="5.421E-18 5.5511E-17 0.013063"
        rpy="0 0 0" />
      <mass
        value="0.01" />
      <inertia
        ixx="5.2784E-08"
        ixy="3.0014E-25"
        ixz="-1.0147E-12"
        iyy="5.278E-08"
        iyz="0"
        izz="5.278E-08" />
    </inertial>
    <visual>
      <origin
        xyz="0 0 0"
        rpy="0 0 0" />
      <geometry>
        <mesh
          filename="package://CK_9_urdf/meshes/link_3.STL" />
      </geometry>
      <material
        name="">
        <color
          rgba="0.79216 0.81961 0.93333 1" />
      </material>
    </visual>
    <collision>
      <origin
        xyz="0 0 0"
        rpy="0 0 0" />
      <geometry>
        <mesh
          filename="package://CK_9_urdf/meshes/link_3.STL" />
      </geometry>
    </collision>
  </link>
  <joint
    name="joint_3"
    type="continuous">
    <origin
      xyz="-0.13117 -0.016788 -0.15512"
      rpy="1.5708 -1.5708 0" />
    <parent
      link="link_2" />
    <child
      link="link_3" />
    <axis
      xyz="0 0 0" />
  </joint>
  <link
    name="link_4">
    <inertial>
      <origin
        xyz="3.2526E-18 0 0.013063"
        rpy="0 0 0" />
      <mass
        value="1" />
      <inertia
        ixx="5.2784E-08"
        ixy="-3.0044E-25"
        ixz="-1.0147E-12"
        iyy="5.278E-08"
        iyz="0"
        izz="5.278E-08" />
    </inertial>
    <visual>
      <origin
        xyz="0 0 0"
        rpy="0 0 0" />
      <geometry>
        <mesh
          filename="package://CK_9_urdf/meshes/link_4.STL" />
      </geometry>
      <material
        name="">
        <color
          rgba="0.79216 0.81961 0.93333 1" />
      </material>
    </visual>
    <collision>
      <origin
        xyz="0 0 0"
        rpy="0 0 0" />
      <geometry>
        <mesh
          filename="package://CK_9_urdf/meshes/link_4.STL" />
      </geometry>
    </collision>
  </link>
  <joint
    name="joint_4"
    type="continuous">
    <origin
      xyz="9.1536E-05 -0.26296 -0.008"
      rpy="0 0 0" />
    <parent
      link="link_3" />
    <child
      link="link_4" />
    <axis
      xyz="0 0 0" />
  </joint>
</robot>